Workbook

Sheet mercancia
A1: ID_Factura | B1: Fecha_Emision | C1: Proveedor | D1: NIT_Proveedor | E1: Item_Descripcion | F1: Cantidad | G1: Valor_Unitario_Antes_de_IVA | H1: Subtotal | I1: IVA_19 | J1: Valor_Total_Factura | K1: Tarifa_Retencion_Fuente | L1: Valor_ReteFuente | M1: Tarifa_ReteICA_Medellin | N1: Valor_ReteICA | O1: Neto_a_Pagar | Q1: AUX_Proveedores | R1: AUX_Prov_NIT | S1: AUX_NIT
A2: ="FE-"&TEXT(1000+ROW()-1,"0000") -> FE-1001 | B2: =DATE(2026,1,1)+RANDBETWEEN(0,119) -> 46048 | C2: {=INDEX($Q$2:$Q$16,RANDBETWEEN(1,15))} -> Tornillería Nacional del Valle de Aburrá | D2: =VLOOKUP(C2,$R$2:$S$16,2,FALSE) -> 900.890.123-8 | E2: {=INDEX($R$2:$R$31,RANDBETWEEN(1,30))} -> Ferretería Antioqueña Ltda. | F2: =RANDBETWEEN(1,50) -> 5 | G2: =MROUND(RANDBETWEEN(1500,850000),100) -> 551700 | H2: =F2*G2 -> 2758500 | I2: =ROUND(H2*0.19,0) -> 524115 | J2: =H2+I2 -> 3282615 | K2: =IF(RANDBETWEEN(0,1)=0,0.025,0.035) -> 0.035 | L2: =ROUND(H2*K2,0) -> 96548 | M2: =0.01104 -> 0.01104 | N2: =ROUND(H2*M2,0) -> 30454 | O2: =J2-L2-N2 -> 3155613 | Q2: Aceros de la Montaña S.A.S. | R2: =Q2 -> Aceros de la Montaña S.A.S. | S2: 900.123.456-1
A3: ="FE-"&TEXT(1000+ROW()-1,"0000") -> FE-1002 | B3: =DATE(2026,1,1)+RANDBETWEEN(0,119) -> 46046 | C3: {=INDEX($Q$2:$Q$16,RANDBETWEEN(1,15))} -> Ferretería Antioqueña Ltda. | D3: =VLOOKUP(C3,$R$2:$S$16,2,FALSE) -> 900.234.567-2 | E3: {=INDEX($R$2:$R$31,RANDBETWEEN(1,30))} -> Lámina de drywall 1.22x2.44m | F3: =RANDBETWEEN(1,50) -> 9 | G3: =MROUND(RANDBETWEEN(1500,850000),100) -> 301800 | H3: =F3*G3 -> 2716200 | I3: =ROUND(H3*0.19,0) -> 516078 | J3: =H3+I3 -> 3232278 | K3: =IF(RANDBETWEEN(0,1)=0,0.025,0.035) -> 0.025 | L3: =ROUND(H3*K3,0) -> 67905 | M3: =0.01104 -> 0.01104 | N3: =ROUND(H3*M3,0) -> 29987 | O3: =J3-L3-N3 -> 3134386 | Q3: Ferretería Antioqueña Ltda. | R3: =Q3 -> Ferretería Antioqueña Ltda. | S3: 900.234.567-2
A4: ="FE-"&TEXT(1000+ROW()-1,"0000") -> FE-1003 | B4: =DATE(2026,1,1)+RANDBETWEEN(0,119) -> 46066 | C4: {=INDEX($Q$2:$Q$16,RANDBETWEEN(1,15))} -> Hierros y Mallas Bello S.A.S. | D4: =VLOOKUP(C4,$R$2:$S$16,2,FALSE) -> 900.901.234-9 | E4: {=INDEX($R$2:$R$31,RANDBETWEEN(1,30))} -> Triturado 1/2" - bulto | F4: =RANDBETWEEN(1,50) -> 14 | G4: =MROUND(RANDBETWEEN(1500,850000),100) -> 809100 | H4: =F4*G4 -> 11327400 | I4: =ROUND(H4*0.19,0) -> 2152206 | J4: =H4+I4 -> 13479606 | K4: =IF(RANDBETWEEN(0,1)=0,0.025,0.035) -> 0.025 | L4: =ROUND(H4*K4,0) -> 283185 | M4: =0.01104 -> 0.01104 | N4: =ROUND(H4*M4,0) -> 125054 | O4: =J4-L4-N4 -> 13071367 | Q4: Distribuidora El Martillo de Oro S.A.S. | R4: =Q4 -> Distribuidora El Martillo de Oro S.A.S. | S4: 900.345.678-3
A5: ="FE-"&TEXT(1000+ROW()-1,"0000") -> FE-1004 | B5: =DATE(2026,1,1)+RANDBETWEEN(0,119) -> 46037 | C5: {=INDEX($Q$2:$Q$16,RANDBETWEEN(1,15))} -> Cementos y Materiales Paisa S.A. | D5: =VLOOKUP(C5,$R$2:$S$16,2,FALSE) -> 900.456.789-4 | E5: {=INDEX($R$2:$R$31,RANDBETWEEN(1,30))} -> Bloque de concreto 10x20x40 | F5: =RANDBETWEEN(1,50) -> 25 | G5: =MROUND(RANDBETWEEN(1500,850000),100) -> 205200 | H5: =F5*G5 -> 5130000 | I5: =ROUND(H5*0.19,0) -> 974700 | J5: =H5+I5 -> 6104700 | K5: =IF(RANDBETWEEN(0,1)=0,0.025,0.035) -> 0.025 | L5: =ROUND(H5*K5,0) -> 128250 | M5: =0.01104 -> 0.01104 | N5: =ROUND(H5*M5,0) -> 56635 | O5: =J5-L5-N5 -> 5919815 | Q5: Cementos y Materiales Paisa S.A. | R5: =Q5 -> Cementos y Materiales Paisa S.A. | S5: 900.456.789-4
A6: ="FE-"&TEXT(1000+ROW()-1,"0000") -> FE-1005 | B6: =DATE(2026,1,1)+RANDBETWEEN(0,119) -> 46140 | C6: {=INDEX($Q$2:$Q$16,RANDBETWEEN(1,15))} -> Aceros de la Montaña S.A.S. | D6: =VLOOKUP(C6,$R$2:$S$16,2,FALSE) -> 900.123.456-1 | E6: {=INDEX($R$2:$R$31,RANDBETWEEN(1,30))} -> Herramientas Industriales Medellín S.A.S. | F6: =RANDBETWEEN(1,50) -> 41 | G6: =MROUND(RANDBETWEEN(1500,850000),100) -> 586400 | H6: =F6*G6 -> 24042400 | I6: =ROUND(H6*0.19,0) -> 4568056 | J6: =H6+I6 -> 28610456 | K6: =IF(RANDBETWEEN(0,1)=0,0.025,0.035) -> 0.035 | L6: =ROUND(H6*K6,0) -> 841484 | M6: =0.01104 -> 0.01104 | N6: =ROUND(H6*M6,0) -> 265428 | O6: =J6-L6-N6 -> 27503544 | Q6: Herramientas Industriales Medellín S.A.S. | R6: =Q6 -> Herramientas Industriales Medellín S.A.S. | S6: 900.567.890-5
A7: ="FE-"&TEXT(1000+ROW()-1,"0000") -> FE-1006 | B7: =DATE(2026,1,1)+RANDBETWEEN(0,119) -> 46025 | C7: {=INDEX($Q$2:$Q$16,RANDBETWEEN(1,15))} -> Pinturas y Acabados Aburrá S.A.S. | D7: =VLOOKUP(C7,$R$2:$S$16,2,FALSE) -> 900.789.012-7 | E7: {=INDEX($R$2:$R$31,RANDBETWEEN(1,30))} -> Herramientas Industriales Medellín S.A.S. | F7: =RANDBETWEEN(1,50) -> 28 | G7: =MROUND(RANDBETWEEN(1500,850000),100) -> 335400 | H7: =F7*G7 -> 9391200 | I7: =ROUND(H7*0.19,0) -> 1784328 | J7: =H7+I7 -> 11175528 | K7: =IF(RANDBETWEEN(0,1)=0,0.025,0.035) -> 0.025 | L7: =ROUND(H7*K7,0) -> 234780 | M7: =0.01104 -> 0.01104 | N7: =ROUND(H7*M7,0) -> 103679 | O7: =J7-L7-N7 -> 10837069 | Q7: Suministros Ferreteros La 80 Ltda. | R7: =Q7 -> Suministros Ferreteros La 80 Ltda. | S7: 900.678.901-6
A8: ="FE-"&TEXT(1000+ROW()-1,"0000") -> FE-1007 | B8: =DATE(2026,1,1)+RANDBETWEEN(0,119) -> 46120 | C8: {=INDEX($Q$2:$Q$16,RANDBETWEEN(1,15))} -> Tornillería Nacional del Valle de Aburrá | D8: =VLOOKUP(C8,$R$2:$S$16,2,FALSE) -> 900.890.123-8 | E8: {=INDEX($R$2:$R$31,RANDBETWEEN(1,30))} -> Tornillería Nacional del Valle de Aburrá | F8: =RANDBETWEEN(1,50) -> 10 | G8: =MROUND(RANDBETWEEN(1500,850000),100) -> 14200 | H8: =F8*G8 -> 142000 | I8: =ROUND(H8*0.19,0) -> 26980 | J8: =H8+I8 -> 168980 | K8: =IF(RANDBETWEEN(0,1)=0,0.025,0.035) -> 0.025 | L8: =ROUND(H8*K8,0) -> 3550 | M8: =0.01104 -> 0.01104 | N8: =ROUND(H8*M8,0) -> 1568 | O8: =J8-L8-N8 -> 163862 | Q8: Pinturas y Acabados Aburrá S.A.S. | R8: =Q8 -> Pinturas y Acabados Aburrá S.A.S. | S8: 900.789.012-7
A9: ="FE-"&TEXT(1000+ROW()-1,"0000") -> FE-1008 | B9: =DATE(2026,1,1)+RANDBETWEEN(0,119) -> 46027 | C9: {=INDEX($Q$2:$Q$16,RANDBETWEEN(1,15))} -> Herramientas Industriales Medellín S.A.S. | D9: =VLOOKUP(C9,$R$2:$S$16,2,FALSE) -> 900.567.890-5 | E9: {=INDEX($R$2:$R$31,RANDBETWEEN(1,30))} -> Ladrillo tolete macizo | F9: =RANDBETWEEN(1,50) -> 3 | G9: =MROUND(RANDBETWEEN(1500,850000),100) -> 691300 | H9: =F9*G9 -> 2073900 | I9: =ROUND(H9*0.19,0) -> 394041 | J9: =H9+I9 -> 2467941 | K9: =IF(RANDBETWEEN(0,1)=0,0.025,0.035) -> 0.035 | L9: =ROUND(H9*K9,0) -> 72587 | M9: =0.01104 -> 0.01104 | N9: =ROUND(H9*M9,0) -> 22896 | O9: =J9-L9-N9 -> 2372458 | Q9: Tornillería Nacional del Valle de Aburrá | R9: =Q9 -> Tornillería Nacional del Valle de Aburrá | S9: 900.890.123-8
A10: ="FE-"&TEXT(1000+ROW()-1,"0000") -> FE-1009 | B10: =DATE(2026,1,1)+RANDBETWEEN(0,119) -> 46037 | C10: {=INDEX($Q$2:$Q$16,RANDBETWEEN(1,15))} -> Tubos y Conexiones Envigado Ltda. | D10: =VLOOKUP(C10,$R$2:$S$16,2,FALSE) -> 901.012.345-0 | E10: {=INDEX($R$2:$R$31,RANDBETWEEN(1,30))} -> Destornillador de pala 1/4" | F10: =RANDBETWEEN(1,50) -> 18 | G10: =MROUND(RANDBETWEEN(1500,850000),100) -> 236900 | H10: =F10*G10 -> 4264200 | I10: =ROUND(H10*0.19,0) -> 810198 | J10: =H10+I10 -> 5074398 | K10: =IF(RANDBETWEEN(0,1)=0,0.025,0.035) -> 0.025 | L10: =ROUND(H10*K10,0) -> 106605 | M10: =0.01104 -> 0.01104 | N10: =ROUND(H10*M10,0) -> 47077 | O10: =J10-L10-N10 -> 4920716 | Q10: Hierros y Mallas Bello S.A.S. | R10: =Q10 -> Hierros y Mallas Bello S.A.S. | S10: 900.901.234-9
A11: ="FE-"&TEXT(1000+ROW()-1,"0000") -> FE-1010 | B11: =DATE(2026,1,1)+RANDBETWEEN(0,119) -> 46117 | C11: {=INDEX($Q$2:$Q$16,RANDBETWEEN(1,15))} -> Acabados y Construcción Poblado S.A.S. | D11: =VLOOKUP(C11,$R$2:$S$16,2,FALSE) -> 901.567.890-5 | E11: {=INDEX($R$2:$R$31,RANDBETWEEN(1,30))} -> Guantes de carnaza par | F11: =RANDBETWEEN(1,50) -> 1 | G11: =MROUND(RANDBETWEEN(1500,850000),100) -> 223500 | H11: =F11*G11 -> 223500 | I11: =ROUND(H11*0.19,0) -> 42465 | J11: =H11+I11 -> 265965 | K11: =IF(RANDBETWEEN(0,1)=0,0.025,0.035) -> 0.035 | L11: =ROUND(H11*K11,0) -> 7823 | M11: =0.01104 -> 0.01104 | N11: =ROUND(H11*M11,0) -> 2467 | O11: =J11-L11-N11 -> 255675 | Q11: Tubos y Conexiones Envigado Ltda. | R11: =Q11 -> Tubos y Conexiones Envigado Ltda. | S11: 901.012.345-0
A12: ="FE-"&TEXT(1000+ROW()-1,"0000") -> FE-1011 | B12: =DATE(2026,1,1)+RANDBETWEEN(0,119) -> 46041 | C12: {=INDEX($Q$2:$Q$16,RANDBETWEEN(1,15))} -> Materiales La Estrella S.A.S. | D12: =VLOOKUP(C12,$R$2:$S$16,2,FALSE) -> 901.345.678-3 | E12: {=INDEX($R$2:$R$31,RANDBETWEEN(1,30))} -> Guantes de carnaza par | F12: =RANDBETWEEN(1,50) -> 44 | G12: =MROUND(RANDBETWEEN(1500,850000),100) -> 266700 | H12: =F12*G12 -> 11734800 | I12: =ROUND(H12*0.19,0) -> 2229612 | J12: =H12+I12 -> 13964412 | K12: =IF(RANDBETWEEN(0,1)=0,0.025,0.035) -> 0.025 | L12: =ROUND(H12*K12,0) -> 293370 | M12: =0.01104 -> 0.01104 | N12: =ROUND(H12*M12,0) -> 129552 | O12: =J12-L12-N12 -> 13541490 | Q12: El Constructor S.A.S. | R12: =Q12 -> El Constructor S.A.S. | S12: 901.123.456-1
A13: ="FE-"&TEXT(1000+ROW()-1,"0000") -> FE-1012 | B13: =DATE(2026,1,1)+RANDBETWEEN(0,119) -> 46076 | C13: {=INDEX($Q$2:$Q$16,RANDBETWEEN(1,15))} -> Cementos y Materiales Paisa S.A. | D13: =VLOOKUP(C13,$R$2:$S$16,2,FALSE) -> 900.456.789-4 | E13: {=INDEX($R$2:$R$31,RANDBETWEEN(1,30))} -> Tornillería Nacional del Valle de Aburrá | F13: =RANDBETWEEN(1,50) -> 4 | G13: =MROUND(RANDBETWEEN(1500,850000),100) -> 542700 | H13: =F13*G13 -> 2170800 | I13: =ROUND(H13*0.19,0) -> 412452 | J13: =H13+I13 -> 2583252 | K13: =IF(RANDBETWEEN(0,1)=0,0.025,0.035) -> 0.025 | L13: =ROUND(H13*K13,0) -> 54270 | M13: =0.01104 -> 0.01104 | N13: =ROUND(H13*M13,0) -> 23966 | O13: =J13-L13-N13 -> 2505016 | Q13: Ferromax Colombia S.A.S. | R13: =Q13 -> Ferromax Colombia S.A.S. | S13: 901.234.567-2
... A16: ="FE-"&TEXT(1000+ROW()-1,"0000") -> FE-1015 | B16: =DATE(2026,1,1)+RANDBETWEEN(0,119) -> 46024 | C16: {=INDEX($Q$2:$Q$16,RANDBETWEEN(1,15))} -> Materiales La Estrella S.A.S. | D16: =VLOOKUP(C16,$R$2:$S$16,2,FALSE) -> 901.345.678-3 | E16: {=INDEX($R$2:$R$31,RANDBETWEEN(1,30))} -> Materiales La Estrella S.A.S. | F16: =RANDBETWEEN(1,50) -> 33 | G16: =MROUND(RANDBETWEEN(1500,850000),100) -> 376000 | H16: =F16*G16 -> 12408000 | I16: =ROUND(H16*0.19,0) -> 2357520 | J16: =H16+I16 -> 14765520 | K16: =IF(RANDBETWEEN(0,1)=0,0.025,0.035) -> 0.025 | L16: =ROUND(H16*K16,0) -> 310200 | M16: =0.01104 -> 0.01104 | N16: =ROUND(H16*M16,0) -> 136984 | O16: =J16-L16-N16 -> 14318336 | Q16: Acabados y Construcción Poblado S.A.S. | R16: =Q16 -> Acabados y Construcción Poblado S.A.S. | S16: 901.567.890-5
A17: ="FE-"&TEXT(1000+ROW()-1,"0000") -> FE-1016 | B17: =DATE(2026,1,1)+RANDBETWEEN(0,119) -> 46046 | C17: {=INDEX($Q$2:$Q$16,RANDBETWEEN(1,15))} -> Aceros de la Montaña S.A.S. | D17: =VLOOKUP(C17,$R$2:$S$16,2,FALSE) -> 900.123.456-1 | E17: {=INDEX($R$2:$R$31,RANDBETWEEN(1,30))} -> Ferretería Antioqueña Ltda. | F17: =RANDBETWEEN(1,50) -> 18 | G17: =MROUND(RANDBETWEEN(1500,850000),100) -> 665700 | H17: =F17*G17 -> 11982600 | I17: =ROUND(H17*0.19,0) -> 2276694 | J17: =H17+I17 -> 14259294 | K17: =IF(RANDBETWEEN(0,1)=0,0.025,0.035) -> 0.025 | L17: =ROUND(H17*K17,0) -> 299565 | M17: =0.01104 -> 0.01104 | N17: =ROUND(H17*M17,0) -> 132288 | O17: =J17-L17-N17 -> 13827441 | R17: Llave de tubo 14"
A18: ="FE-"&TEXT(1000+ROW()-1,"0000") -> FE-1017 | B18: =DATE(2026,1,1)+RANDBETWEEN(0,119) -> 46093 | C18: {=INDEX($Q$2:$Q$16,RANDBETWEEN(1,15))} -> Aceros de la Montaña S.A.S. | D18: =VLOOKUP(C18,$R$2:$S$16,2,FALSE) -> 900.123.456-1 | E18: {=INDEX($R$2:$R$31,RANDBETWEEN(1,30))} -> Llave de tubo 14" | F18: =RANDBETWEEN(1,50) -> 27 | G18: =MROUND(RANDBETWEEN(1500,850000),100) -> 199100 | H18: =F18*G18 -> 5375700 | I18: =ROUND(H18*0.19,0) -> 1021383 | J18: =H18+I18 -> 6397083 | K18: =IF(RANDBETWEEN(0,1)=0,0.025,0.035) -> 0.025 | L18: =ROUND(H18*K18,0) -> 134393 | M18: =0.01104 -> 0.01104 | N18: =ROUND(H18*M18,0) -> 59348 | O18: =J18-L18-N18 -> 6203342 | R18: Destornillador de pala 1/4"
A19: ="FE-"&TEXT(1000+ROW()-1,"0000") -> FE-1018 | B19: =DATE(2026,1,1)+RANDBETWEEN(0,119) -> 46043 | C19: {=INDEX($Q$2:$Q$16,RANDBETWEEN(1,15))} -> Pinturas y Acabados Aburrá S.A.S. | D19: =VLOOKUP(C19,$R$2:$S$16,2,FALSE) -> 900.789.012-7 | E19: {=INDEX($R$2:$R$31,RANDBETWEEN(1,30))} -> Aceros de la Montaña S.A.S. | F19: =RANDBETWEEN(1,50) -> 5 | G19: =MROUND(RANDBETWEEN(1500,850000),100) -> 776100 | H19: =F19*G19 -> 3880500 | I19: =ROUND(H19*0.19,0) -> 737295 | J19: =H19+I19 -> 4617795 | K19: =IF(RANDBETWEEN(0,1)=0,0.025,0.035) -> 0.035 | L19: =ROUND(H19*K19,0) -> 135818 | M19: =0.01104 -> 0.01104 | N19: =ROUND(H19*M19,0) -> 42841 | O19: =J19-L19-N19 -> 4439136 | R19: Cemento blanco x 5 kg
A20: ="FE-"&TEXT(1000+ROW()-1,"0000") -> FE-1019 | B20: =DATE(2026,1,1)+RANDBETWEEN(0,119) -> 46079 | C20: {=INDEX($Q$2:$Q$16,RANDBETWEEN(1,15))} -> Aceros de la Montaña S.A.S. | D20: =VLOOKUP(C20,$R$2:$S$16,2,FALSE) -> 900.123.456-1 | E20: {=INDEX($R$2:$R$31,RANDBETWEEN(1,30))} -> Guantes de carnaza par | F20: =RANDBETWEEN(1,50) -> 47 | G20: =MROUND(RANDBETWEEN(1500,850000),100) -> 746000 | H20: =F20*G20 -> 35062000 | I20: =ROUND(H20*0.19,0) -> 6661780 | J20: =H20+I20 -> 41723780 | K20: =IF(RANDBETWEEN(0,1)=0,0.025,0.035) -> 0.035 | L20: =ROUND(H20*K20,0) -> 1227170 | M20: =0.01104 -> 0.01104 | N20: =ROUND(H20*M20,0) -> 387084 | O20: =J20-L20-N20 -> 40109526 | R20: Arena de río - bulto
A21: ="FE-"&TEXT(1000+ROW()-1,"0000") -> FE-1020 | B21: =DATE(2026,1,1)+RANDBETWEEN(0,119) -> 46040 | C21: {=INDEX($Q$2:$Q$16,RANDBETWEEN(1,15))} -> Aceros de la Montaña S.A.S. | D21: =VLOOKUP(C21,$R$2:$S$16,2,FALSE) -> 900.123.456-1 | E21: {=INDEX($R$2:$R$31,RANDBETWEEN(1,30))} -> Cementos y Materiales Paisa S.A. | F21: =RANDBETWEEN(1,50) -> 32 | G21: =MROUND(RANDBETWEEN(1500,850000),100) -> 604600 | H21: =F21*G21 -> 19347200 | I21: =ROUND(H21*0.19,0) -> 3675968 | J21: =H21+I21 -> 23023168 | K21: =IF(RANDBETWEEN(0,1)=0,0.025,0.035) -> 0.035 | L21: =ROUND(H21*K21,0) -> 677152 | M21: =0.01104 -> 0.01104 | N21: =ROUND(H21*M21,0) -> 213593 | O21: =J21-L21-N21 -> 22132423 | R21: Triturado 1/2" - bulto
A22: ="FE-"&TEXT(1000+ROW()-1,"0000") -> FE-1021 | B22: =DATE(2026,1,1)+RANDBETWEEN(0,119) -> 46086 | C22: {=INDEX($Q$2:$Q$16,RANDBETWEEN(1,15))} -> Cementos y Materiales Paisa S.A. | D22: =VLOOKUP(C22,$R$2:$S$16,2,FALSE) -> 900.456.789-4 | E22: {=INDEX($R$2:$R$31,RANDBETWEEN(1,30))} -> Pinturas y Acabados Aburrá S.A.S. | F22: =RANDBETWEEN(1,50) -> 29 | G22: =MROUND(RANDBETWEEN(1500,850000),100) -> 311400 | H22: =F22*G22 -> 9030600 | I22: =ROUND(H22*0.19,0) -> 1715814 | J22: =H22+I22 -> 10746414 | K22: =IF(RANDBETWEEN(0,1)=0,0.025,0.035) -> 0.025 | L22: =ROUND(H22*K22,0) -> 225765 | M22: =0.01104 -> 0.01104 | N22: =ROUND(H22*M22,0) -> 99698 | O22: =J22-L22-N22 -> 10420951 | R22: Bloque de concreto 10x20x40
A23: ="FE-"&TEXT(1000+ROW()-1,"0000") -> FE-1022 | B23: =DATE(2026,1,1)+RANDBETWEEN(0,119) -> 46137 | C23: {=INDEX($Q$2:$Q$16,RANDBETWEEN(1,15))} -> Acabados y Construcción Poblado S.A.S. | D23: =VLOOKUP(C23,$R$2:$S$16,2,FALSE) -> 901.567.890-5 | E23: {=INDEX($R$2:$R$31,RANDBETWEEN(1,30))} -> Materiales La Estrella S.A.S. | F23: =RANDBETWEEN(1,50) -> 32 | G23: =MROUND(RANDBETWEEN(1500,850000),100) -> 230900 | H23: =F23*G23 -> 7388800 | I23: =ROUND(H23*0.19,0) -> 1403872 | J23: =H23+I23 -> 8792672 | K23: =IF(RANDBETWEEN(0,1)=0,0.025,0.035) -> 0.035 | L23: =ROUND(H23*K23,0) -> 258608 | M23: =0.01104 -> 0.01104 | N23: =ROUND(H23*M23,0) -> 81572 | O23: =J23-L23-N23 -> 8452492 | R23: Ladrillo tolete macizo
A24: ="FE-"&TEXT(1000+ROW()-1,"0000") -> FE-1023 | B24: =DATE(2026,1,1)+RANDBETWEEN(0,119) -> 46098 | C24: {=INDEX($Q$2:$Q$16,RANDBETWEEN(1,15))} -> Ferromax Colombia S.A.S. | D24: =VLOOKUP(C24,$R$2:$S$16,2,FALSE) -> 901.234.567-2 | E24: {=INDEX($R$2:$R$31,RANDBETWEEN(1,30))} -> Cemento blanco x 5 kg | F24: =RANDBETWEEN(1,50) -> 44 | G24: =MROUND(RANDBETWEEN(1500,850000),100) -> 353800 | H24: =F24*G24 -> 15567200 | I24: =ROUND(H24*0.19,0) -> 2957768 | J24: =H24+I24 -> 18524968 | K24: =IF(RANDBETWEEN(0,1)=0,0.025,0.035) -> 0.025 | L24: =ROUND(H24*K24,0) -> 389180 | M24: =0.01104 -> 0.01104 | N24: =ROUND(H24*M24,0) -> 171862 | O24: =J24-L24-N24 -> 17963926 | R24: Teja eternit ondulada No. 6
A25: ="FE-"&TEXT(1000+ROW()-1,"0000") -> FE-1024 | B25: =DATE(2026,1,1)+RANDBETWEEN(0,119) -> 46051 | C25: {=INDEX($Q$2:$Q$16,RANDBETWEEN(1,15))} -> Tornillería Nacional del Valle de Aburrá | D25: =VLOOKUP(C25,$R$2:$S$16,2,FALSE) -> 900.890.123-8 | E25: {=INDEX($R$2:$R$31,RANDBETWEEN(1,30))} -> Esmeril angular 4-1/2" 850W | F25: =RANDBETWEEN(1,50) -> 22 | G25: =MROUND(RANDBETWEEN(1500,850000),100) -> 136000 | H25: =F25*G25 -> 2992000 | I25: =ROUND(H25*0.19,0) -> 568480 | J25: =H25+I25 -> 3560480 | K25: =IF(RANDBETWEEN(0,1)=0,0.025,0.035) -> 0.035 | L25: =ROUND(H25*K25,0) -> 104720 | M25: =0.01104 -> 0.01104 | N25: =ROUND(H25*M25,0) -> 33032 | O25: =J25-L25-N25 -> 3422728 | R25: Lámina de drywall 1.22x2.44m
A26: ="FE-"&TEXT(1000+ROW()-1,"0000") -> FE-1025 | B26: =DATE(2026,1,1)+RANDBETWEEN(0,119) -> 46032 | C26: {=INDEX($Q$2:$Q$16,RANDBETWEEN(1,15))} -> El Constructor S.A.S. | D26: =VLOOKUP(C26,$R$2:$S$16,2,FALSE) -> 901.123.456-1 | E26: {=INDEX($R$2:$R$31,RANDBETWEEN(1,30))} -> Bloque de concreto 10x20x40 | F26: =RANDBETWEEN(1,50) -> 36 | G26: =MROUND(RANDBETWEEN(1500,850000),100) -> 20700 | H26: =F26*G26 -> 745200 | I26: =ROUND(H26*0.19,0) -> 141588 | J26: =H26+I26 -> 886788 | K26: =IF(RANDBETWEEN(0,1)=0,0.025,0.035) -> 0.025 | L26: =ROUND(H26*K26,0) -> 18630 | M26: =0.01104 -> 0.01104 | N26: =ROUND(H26*M26,0) -> 8227 | O26: =J26-L26-N26 -> 859931 | R26: Carretilla buggy reforzada
A27: ="FE-"&TEXT(1000+ROW()-1,"0000") -> FE-1026 | B27: =DATE(2026,1,1)+RANDBETWEEN(0,119) -> 46096 | C27: {=INDEX($Q$2:$Q$16,RANDBETWEEN(1,15))} -> Suministros Ferreteros La 80 Ltda. | D27: =VLOOKUP(C27,$R$2:$S$16,2,FALSE) -> 900.678.901-6 | E27: {=INDEX($R$2:$R$31,RANDBETWEEN(1,30))} -> Lámina de drywall 1.22x2.44m | F27: =RANDBETWEEN(1,50) -> 15 | G27: =MROUND(RANDBETWEEN(1500,850000),100) -> 426400 | H27: =F27*G27 -> 6396000 | I27: =ROUND(H27*0.19,0) -> 1215240 | J27: =H27+I27 -> 7611240 | K27: =IF(RANDBETWEEN(0,1)=0,0.025,0.035) -> 0.035 | L27: =ROUND(H27*K27,0) -> 223860 | M27: =0.01104 -> 0.01104 | N27: =ROUND(H27*M27,0) -> 70612 | O27: =J27-L27-N27 -> 7316768 | R27: Pala cuadrada con cabo
A28: ="FE-"&TEXT(1000+ROW()-1,"0000") -> FE-1027 | B28: =DATE(2026,1,1)+RANDBETWEEN(0,119) -> 46057 | C28: {=INDEX($Q$2:$Q$16,RANDBETWEEN(1,15))} -> Materiales La Estrella S.A.S. | D28: =VLOOKUP(C28,$R$2:$S$16,2,FALSE) -> 901.345.678-3 | E28: {=INDEX($R$2:$R$31,RANDBETWEEN(1,30))} -> Tornillería Nacional del Valle de Aburrá | F28: =RANDBETWEEN(1,50) -> 1 | G28: =MROUND(RANDBETWEEN(1500,850000),100) -> 218000 | H28: =F28*G28 -> 218000 | I28: =ROUND(H28*0.19,0) -> 41420 | J28: =H28+I28 -> 259420 | K28: =IF(RANDBETWEEN(0,1)=0,0.025,0.035) -> 0.025 | L28: =ROUND(H28*K28,0) -> 5450 | M28: =0.01104 -> 0.01104 | N28: =ROUND(H28*M28,0) -> 2407 | O28: =J28-L28-N28 -> 251563 | R28: Guantes de carnaza par
... A31: ="FE-"&TEXT(1000+ROW()-1,"0000") -> FE-1030 | B31: =DATE(2026,1,1)+RANDBETWEEN(0,119) -> 46035 | C31: {=INDEX($Q$2:$Q$16,RANDBETWEEN(1,15))} -> Ferromax Colombia S.A.S. | D31: =VLOOKUP(C31,$R$2:$S$16,2,FALSE) -> 901.234.567-2 | E31: {=INDEX($R$2:$R$31,RANDBETWEEN(1,30))} -> Lámina de drywall 1.22x2.44m | F31: =RANDBETWEEN(1,50) -> 2 | G31: =MROUND(RANDBETWEEN(1500,850000),100) -> 534500 | H31: =F31*G31 -> 1069000 | I31: =ROUND(H31*0.19,0) -> 203110 | J31: =H31+I31 -> 1272110 | K31: =IF(RANDBETWEEN(0,1)=0,0.025,0.035) -> 0.035 | L31: =ROUND(H31*K31,0) -> 37415 | M31: =0.01104 -> 0.01104 | N31: =ROUND(H31*M31,0) -> 11802 | O31: =J31-L31-N31 -> 1222893 | R31: Esmeril angular 4-1/2" 850W
A32: ="FE-"&TEXT(1000+ROW()-1,"0000") -> FE-1031 | B32: =DATE(2026,1,1)+RANDBETWEEN(0,119) -> 46139 | C32: {=INDEX($Q$2:$Q$16,RANDBETWEEN(1,15))} -> Herramientas Industriales Medellín S.A.S. | D32: =VLOOKUP(C32,$R$2:$S$16,2,FALSE) -> 900.567.890-5 | E32: {=INDEX($R$2:$R$31,RANDBETWEEN(1,30))} -> Teja eternit ondulada No. 6 | F32: =RANDBETWEEN(1,50) -> 45 | G32: =MROUND(RANDBETWEEN(1500,850000),100) -> 644400 | H32: =F32*G32 -> 28998000 | I32: =ROUND(H32*0.19,0) -> 5509620 | J32: =H32+I32 -> 34507620 | K32: =IF(RANDBETWEEN(0,1)=0,0.025,0.035) -> 0.035 | L32: =ROUND(H32*K32,0) -> 1014930 | M32: =0.01104 -> 0.01104 | N32: =ROUND(H32*M32,0) -> 320138 | O32: =J32-L32-N32 -> 33172552
A33: ="FE-"&TEXT(1000+ROW()-1,"0000") -> FE-1032 | B33: =DATE(2026,1,1)+RANDBETWEEN(0,119) -> 46041 | C33: {=INDEX($Q$2:$Q$16,RANDBETWEEN(1,15))} -> Acabados y Construcción Poblado S.A.S. | D33: =VLOOKUP(C33,$R$2:$S$16,2,FALSE) -> 901.567.890-5 | E33: {=INDEX($R$2:$R$31,RANDBETWEEN(1,30))} -> Casco de seguridad industrial | F33: =RANDBETWEEN(1,50) -> 11 | G33: =MROUND(RANDBETWEEN(1500,850000),100) -> 630600 | H33: =F33*G33 -> 6936600 | I33: =ROUND(H33*0.19,0) -> 1317954 | J33: =H33+I33 -> 8254554 | K33: =IF(RANDBETWEEN(0,1)=0,0.025,0.035) -> 0.035 | L33: =ROUND(H33*K33,0) -> 242781 | M33: =0.01104 -> 0.01104 | N33: =ROUND(H33*M33,0) -> 76580 | O33: =J33-L33-N33 -> 7935193
A34: ="FE-"&TEXT(1000+ROW()-1,"0000") -> FE-1033 | B34: =DATE(2026,1,1)+RANDBETWEEN(0,119) -> 46110 | C34: {=INDEX($Q$2:$Q$16,RANDBETWEEN(1,15))} -> Materiales La Estrella S.A.S. | D34: =VLOOKUP(C34,$R$2:$S$16,2,FALSE) -> 901.345.678-3 | E34: {=INDEX($R$2:$R$31,RANDBETWEEN(1,30))} -> Tubos y Conexiones Envigado Ltda. | F34: =RANDBETWEEN(1,50) -> 1 | G34: =MROUND(RANDBETWEEN(1500,850000),100) -> 459200 | H34: =F34*G34 -> 459200 | I34: =ROUND(H34*0.19,0) -> 87248 | J34: =H34+I34 -> 546448 | K34: =IF(RANDBETWEEN(0,1)=0,0.025,0.035) -> 0.035 | L34: =ROUND(H34*K34,0) -> 16072 | M34: =0.01104 -> 0.01104 | N34: =ROUND(H34*M34,0) -> 5070 | O34: =J34-L34-N34 -> 525306
A35: ="FE-"&TEXT(1000+ROW()-1,"0000") -> FE-1034 | B35: =DATE(2026,1,1)+RANDBETWEEN(0,119) -> 46098 | C35: {=INDEX($Q$2:$Q$16,RANDBETWEEN(1,15))} -> Hierros y Mallas Bello S.A.S. | D35: =VLOOKUP(C35,$R$2:$S$16,2,FALSE) -> 900.901.234-9 | E35: {=INDEX($R$2:$R$31,RANDBETWEEN(1,30))} -> Suministros Ferreteros La 80 Ltda. | F35: =RANDBETWEEN(1,50) -> 32 | G35: =MROUND(RANDBETWEEN(1500,850000),100) -> 261100 | H35: =F35*G35 -> 8355200 | I35: =ROUND(H35*0.19,0) -> 1587488 | J35: =H35+I35 -> 9942688 | K35: =IF(RANDBETWEEN(0,1)=0,0.025,0.035) -> 0.025 | L35: =ROUND(H35*K35,0) -> 208880 | M35: =0.01104 -> 0.01104 | N35: =ROUND(H35*M35,0) -> 92241 | O35: =J35-L35-N35 -> 9641567
A36: ="FE-"&TEXT(1000+ROW()-1,"0000") -> FE-1035 | B36: =DATE(2026,1,1)+RANDBETWEEN(0,119) -> 46031 | C36: {=INDEX($Q$2:$Q$16,RANDBETWEEN(1,15))} -> Tubos y Conexiones Envigado Ltda. | D36: =VLOOKUP(C36,$R$2:$S$16,2,FALSE) -> 901.012.345-0 | E36: {=INDEX($R$2:$R$31,RANDBETWEEN(1,30))} -> Ferretería Antioqueña Ltda. | F36: =RANDBETWEEN(1,50) -> 36 | G36: =MROUND(RANDBETWEEN(1500,850000),100) -> 796400 | H36: =F36*G36 -> 28670400 | I36: =ROUND(H36*0.19,0) -> 5447376 | J36: =H36+I36 -> 34117776 | K36: =IF(RANDBETWEEN(0,1)=0,0.025,0.035) -> 0.025 | L36: =ROUND(H36*K36,0) -> 716760 | M36: =0.01104 -> 0.01104 | N36: =ROUND(H36*M36,0) -> 316521 | O36: =J36-L36-N36 -> 33084495
A37: ="FE-"&TEXT(1000+ROW()-1,"0000") -> FE-1036 | B37: =DATE(2026,1,1)+RANDBETWEEN(0,119) -> 46136 | C37: {=INDEX($Q$2:$Q$16,RANDBETWEEN(1,15))} -> Ferromax Colombia S.A.S. | D37: =VLOOKUP(C37,$R$2:$S$16,2,FALSE) -> 901.234.567-2 | E37: {=INDEX($R$2:$R$31,RANDBETWEEN(1,30))} -> Acabados y Construcción Poblado S.A.S. | F37: =RANDBETWEEN(1,50) -> 11 | G37: =MROUND(RANDBETWEEN(1500,850000),100) -> 329500 | H37: =F37*G37 -> 3624500 | I37: =ROUND(H37*0.19,0) -> 688655 | J37: =H37+I37 -> 4313155 | K37: =IF(RANDBETWEEN(0,1)=0,0.025,0.035) -> 0.025 | L37: =ROUND(H37*K37,0) -> 90613 | M37: =0.01104 -> 0.01104 | N37: =ROUND(H37*M37,0) -> 40014 | O37: =J37-L37-N37 -> 4182528
A38: ="FE-"&TEXT(1000+ROW()-1,"0000") -> FE-1037 | B38: =DATE(2026,1,1)+RANDBETWEEN(0,119) -> 46109 | C38: {=INDEX($Q$2:$Q$16,RANDBETWEEN(1,15))} -> Ferromax Colombia S.A.S. | D38: =VLOOKUP(C38,$R$2:$S$16,2,FALSE) -> 901.234.567-2 | E38: {=INDEX($R$2:$R$31,RANDBETWEEN(1,30))} -> El Constructor S.A.S. | F38: =RANDBETWEEN(1,50) -> 50 | G38: =MROUND(RANDBETWEEN(1500,850000),100) -> 515900 | H38: =F38*G38 -> 25795000 | I38: =ROUND(H38*0.19,0) -> 4901050 | J38: =H38+I38 -> 30696050 | K38: =IF(RANDBETWEEN(0,1)=0,0.025,0.035) -> 0.025 | L38: =ROUND(H38*K38,0) -> 644875 | M38: =0.01104 -> 0.01104 | N38: =ROUND(H38*M38,0) -> 284777 | O38: =J38-L38-N38 -> 29766398
A39: ="FE-"&TEXT(1000+ROW()-1,"0000") -> FE-1038 | B39: =DATE(2026,1,1)+RANDBETWEEN(0,119) -> 46132 | C39: {=INDEX($Q$2:$Q$16,RANDBETWEEN(1,15))} -> Herramientas Industriales Medellín S.A.S. | D39: =VLOOKUP(C39,$R$2:$S$16,2,FALSE) -> 900.567.890-5 | E39: {=INDEX($R$2:$R$31,RANDBETWEEN(1,30))} -> Carretilla buggy reforzada | F39: =RANDBETWEEN(1,50) -> 20 | G39: =MROUND(RANDBETWEEN(1500,850000),100) -> 723800 | H39: =F39*G39 -> 14476000 | I39: =ROUND(H39*0.19,0) -> 2750440 | J39: =H39+I39 -> 17226440 | K39: =IF(RANDBETWEEN(0,1)=0,0.025,0.035) -> 0.025 | L39: =ROUND(H39*K39,0) -> 361900 | M39: =0.01104 -> 0.01104 | N39: =ROUND(H39*M39,0) -> 159815 | O39: =J39-L39-N39 -> 16704725
A40: ="FE-"&TEXT(1000+ROW()-1,"0000") -> FE-1039 | B40: =DATE(2026,1,1)+RANDBETWEEN(0,119) -> 46045 | C40: {=INDEX($Q$2:$Q$16,RANDBETWEEN(1,15))} -> El Constructor S.A.S. | D40: =VLOOKUP(C40,$R$2:$S$16,2,FALSE) -> 901.123.456-1 | E40: {=INDEX($R$2:$R$31,RANDBETWEEN(1,30))} -> El Constructor S.A.S. | F40: =RANDBETWEEN(1,50) -> 12 | G40: =MROUND(RANDBETWEEN(1500,850000),100) -> 140700 | H40: =F40*G40 -> 1688400 | I40: =ROUND(H40*0.19,0) -> 320796 | J40: =H40+I40 -> 2009196 | K40: =IF(RANDBETWEEN(0,1)=0,0.025,0.035) -> 0.035 | L40: =ROUND(H40*K40,0) -> 59094 | M40: =0.01104 -> 0.01104 | N40: =ROUND(H40*M40,0) -> 18640 | O40: =J40-L40-N40 -> 1931462
A41: ="FE-"&TEXT(1000+ROW()-1,"0000") -> FE-1040 | B41: =DATE(2026,1,1)+RANDBETWEEN(0,119) -> 46050 | C41: {=INDEX($Q$2:$Q$16,RANDBETWEEN(1,15))} -> El Constructor S.A.S. | D41: =VLOOKUP(C41,$R$2:$S$16,2,FALSE) -> 901.123.456-1 | E41: {=INDEX($R$2:$R$31,RANDBETWEEN(1,30))} -> Triturado 1/2" - bulto | F41: =RANDBETWEEN(1,50) -> 12 | G41: =MROUND(RANDBETWEEN(1500,850000),100) -> 811600 | H41: =F41*G41 -> 9739200 | I41: =ROUND(H41*0.19,0) -> 1850448 | J41: =H41+I41 -> 11589648 | K41: =IF(RANDBETWEEN(0,1)=0,0.025,0.035) -> 0.025 | L41: =ROUND(H41*K41,0) -> 243480 | M41: =0.01104 -> 0.01104 | N41: =ROUND(H41*M41,0) -> 107521 | O41: =J41-L41-N41 -> 11238647
A42: ="FE-"&TEXT(1000+ROW()-1,"0000") -> FE-1041 | B42: =DATE(2026,1,1)+RANDBETWEEN(0,119) -> 46073 | C42: {=INDEX($Q$2:$Q$16,RANDBETWEEN(1,15))} -> Hierros y Mallas Bello S.A.S. | D42: =VLOOKUP(C42,$R$2:$S$16,2,FALSE) -> 900.901.234-9 | E42: {=INDEX($R$2:$R$31,RANDBETWEEN(1,30))} -> Cemento blanco x 5 kg | F42: =RANDBETWEEN(1,50) -> 24 | G42: =MROUND(RANDBETWEEN(1500,850000),100) -> 210300 | H42: =F42*G42 -> 5047200 | I42: =ROUND(H42*0.19,0) -> 958968 | J42: =H42+I42 -> 6006168 | K42: =IF(RANDBETWEEN(0,1)=0,0.025,0.035) -> 0.035 | L42: =ROUND(H42*K42,0) -> 176652 | M42: =0.01104 -> 0.01104 | N42: =ROUND(H42*M42,0) -> 55721 | O42: =J42-L42-N42 -> 5773795
A43: ="FE-"&TEXT(1000+ROW()-1,"0000") -> FE-1042 | B43: =DATE(2026,1,1)+RANDBETWEEN(0,119) -> 46048 | C43: {=INDEX($Q$2:$Q$16,RANDBETWEEN(1,15))} -> Distribuidora El Martillo de Oro S.A.S. | D43: =VLOOKUP(C43,$R$2:$S$16,2,FALSE) -> 900.345.678-3 | E43: {=INDEX($R$2:$R$31,RANDBETWEEN(1,30))} -> Teja eternit ondulada No. 6 | F43: =RANDBETWEEN(1,50) -> 27 | G43: =MROUND(RANDBETWEEN(1500,850000),100) -> 220600 | H43: =F43*G43 -> 5956200 | I43: =ROUND(H43*0.19,0) -> 1131678 | J43: =H43+I43 -> 7087878 | K43: =IF(RANDBETWEEN(0,1)=0,0.025,0.035) -> 0.025 | L43: =ROUND(H43*K43,0) -> 148905 | M43: =0.01104 -> 0.01104 | N43: =ROUND(H43*M43,0) -> 65756 | O43: =J43-L43-N43 -> 6873217
... A101: ="FE-"&TEXT(1000+ROW()-1,"0000") -> FE-1100 | B101: =DATE(2026,1,1)+RANDBETWEEN(0,119) -> 46075 | C101: {=INDEX($Q$2:$Q$16,RANDBETWEEN(1,15))} -> Distribuciones Itagüí Ferretera Ltda. | D101: =VLOOKUP(C101,$R$2:$S$16,2,FALSE) -> 901.456.789-4 | E101: {=INDEX($R$2:$R$31,RANDBETWEEN(1,30))} -> Suministros Ferreteros La 80 Ltda. | F101: =RANDBETWEEN(1,50) -> 26 | G101: =MROUND(RANDBETWEEN(1500,850000),100) -> 195400 | H101: =F101*G101 -> 5080400 | I101: =ROUND(H101*0.19,0) -> 965276 | J101: =H101+I101 -> 6045676 | K101: =IF(RANDBETWEEN(0,1)=0,0.025,0.035) -> 0.035 | L101: =ROUND(H101*K101,0) -> 177814 | M101: =0.01104 -> 0.01104 | N101: =ROUND(H101*M101,0) -> 56088 | O101: =J101-L101-N101 -> 5811774

Sheet Hoja2
A1: AUX_Proveedores | B1: AUX_NIT
A2: Aceros de la Montaña S.A.S. | B2: 900.123.456-1
A3: Ferretería Antioqueña Ltda. | B3: 900.234.567-2
A4: Distribuidora El Martillo de Oro S.A.S. | B4: 900.345.678-3
A5: Cementos y Materiales Paisa S.A. | B5: 900.456.789-4
A6: Herramientas Industriales Medellín S.A.S. | B6: 900.567.890-5
A7: Suministros Ferreteros La 80 Ltda. | B7: 900.678.901-6
A8: Pinturas y Acabados Aburrá S.A.S. | B8: 900.789.012-7
A9: Tornillería Nacional del Valle de Aburrá | B9: 900.890.123-8
A10: Hierros y Mallas Bello S.A.S. | B10: 900.901.234-9
A11: Tubos y Conexiones Envigado Ltda. | B11: 901.012.345-0
A12: El Constructor S.A.S. | B12: 901.123.456-1
... A16: Acabados y Construcción Poblado S.A.S. | B16: 901.567.890-5

Sheet Gastos_Administrativos
A1: ID_Gasto | B1: Fecha | C1: Concepto_Gasto | D1: Tercero_Proveedor | E1: NIT_CC | F1: Tipo_Gasto | G1: Centro_Costo | H1: Base_Gravable | I1: Tarifa_IVA | J1: Valor_IVA | K1: Valor_Total | L1: Tarifa_ReteFuente | M1: Valor_ReteFuente | N1: Tarifa_ReteIVA | O1: Valor_ReteIVA | P1: Tarifa_ReteICA | Q1: Valor_ReteICA | R1: Neto_a_Pagar | S1: Forma_Pago | T1: Estado | V1: AUX_Concepto | W1: AUX_Tipo | X1: AUX_TarifaRF | Y1: AUX_Proveedor | Z1: AUX_NIT | AB1: AUX_CentroCosto | AC1: AUX_FormaPago | AD1: AUX_Estado
A2: ="GA-"&TEXT(2000+ROW()-2,"0000") -> GA-2000 | B2: =DATE(2026,1,1)+RANDBETWEEN(0,119) -> 46123 | C2: {=INDEX($V$2:$V$31,RANDBETWEEN(1,30))} -> Mantenimiento equipos de cómputo | D2: {=INDEX($Y$2:$Y$26,RANDBETWEEN(1,25))} -> Servientrega S.A. | E2: =INDEX($Z$2:$Z$26,MATCH(D2,$Y$2:$Y$26,0)) -> 860512330-3 | F2: =INDEX($W$2:$W$31,MATCH(C2,$V$2:$V$31,0)) -> Mantenimiento | G2: {=INDEX($AB$2:$AB$6,RANDBETWEEN(1,5))} -> Ventas | H2: =ROUND(RANDBETWEEN(150000,8500000),-2) -> 1469100 | I2: =IF(OR(F2="Servicios Públicos",F2="Financieros",F2="Legales",F2="Seguros"),0,0.19) -> 0.19 | J2: =ROUND(H2*I2,0) -> 279129 | K2: =H2+J2 -> 1748229 | L2: =INDEX($X$2:$X$31,MATCH(C2,$V$2:$V$31,0)) -> 0.04 | M2: =ROUND(H2*L2,0) -> 58764 | N2: =IF(I2=0,0,0.15) -> 0.15 | O2: =ROUND(J2*N2,0) -> 41869 | P2: =0.01104 -> 0.01104 | Q2: =ROUND(H2*P2,0) -> 16219 | R2: =K2-M2-O2-Q2 -> 1631377 | S2: =CHOOSE(RANDBETWEEN(1,3),"Transferencia","Efectivo","Tarjeta crédito") -> Tarjeta crédito | T2: =IF(RANDBETWEEN(1,10)<=8,"Pagado","Pendiente") -> Pagado | V2: Arrendamiento local comercial | W2: Arrendamientos | X2: 0.035 | Y2: Inmobiliaria El Poblado S.A.S. | Z2: 900456789-1 | AB2: Administración | AC2: Transferencia | AD2: Pagado
A3: ="GA-"&TEXT(2000+ROW()-2,"0000") -> GA-2001 | B3: =DATE(2026,1,1)+RANDBETWEEN(0,119) -> 46098 | C3: {=INDEX($V$2:$V$31,RANDBETWEEN(1,30))} -> Suscripción cámara de comercio | D3: {=INDEX($Y$2:$Y$26,RANDBETWEEN(1,25))} -> Facturación Electrónica Alegra S.A.S. | E3: =INDEX($Z$2:$Z$26,MATCH(D3,$Y$2:$Y$26,0)) -> 900912345-0 | F3: =INDEX($W$2:$W$31,MATCH(C3,$V$2:$V$31,0)) -> Legales | G3: {=INDEX($AB$2:$AB$6,RANDBETWEEN(1,5))} -> Ventas | H3: =ROUND(RANDBETWEEN(150000,8500000),-2) -> 8238200 | I3: =IF(OR(F3="Servicios Públicos",F3="Financieros",F3="Legales",F3="Seguros"),0,0.19) -> 0 | J3: =ROUND(H3*I3,0) -> 0 | K3: =H3+J3 -> 8238200 | L3: =INDEX($X$2:$X$31,MATCH(C3,$V$2:$V$31,0)) -> 0 | M3: =ROUND(H3*L3,0) -> 0 | N3: =IF(I3=0,0,0.15) -> 0 | O3: =ROUND(J3*N3,0) -> 0 | P3: =0.01104 -> 0.01104 | Q3: =ROUND(H3*P3,0) -> 90950 | R3: =K3-M3-O3-Q3 -> 8147250 | S3: =CHOOSE(RANDBETWEEN(1,3),"Transferencia","Efectivo","Tarjeta crédito") -> Efectivo | T3: =IF(RANDBETWEEN(1,10)<=8,"Pagado","Pendiente") -> Pagado | V3: Servicio de energía eléctrica | W3: Servicios Públicos | X3: 0 | Y3: EPM - Empresas Públicas de Medellín | Z3: 890904996-1 | AB3: Ventas | AC3: Efectivo | AD3: Pendiente
A4: ="GA-"&TEXT(2000+ROW()-2,"0000") -> GA-2002 | B4: =DATE(2026,1,1)+RANDBETWEEN(0,119) -> 46058 | C4: {=INDEX($V$2:$V$31,RANDBETWEEN(1,30))} -> Publicidad redes sociales | D4: {=INDEX($Y$2:$Y$26,RANDBETWEEN(1,25))} -> Distribuidora Café Aburrá Ltda. | E4: =INDEX($Z$2:$Z$26,MATCH(D4,$Y$2:$Y$26,0)) -> 901890123-7 | F4: =INDEX($W$2:$W$31,MATCH(C4,$V$2:$V$31,0)) -> Publicidad | G4: {=INDEX($AB$2:$AB$6,RANDBETWEEN(1,5))} -> Gerencia | H4: =ROUND(RANDBETWEEN(150000,8500000),-2) -> 773700 | I4: =IF(OR(F4="Servicios Públicos",F4="Financieros",F4="Legales",F4="Seguros"),0,0.19) -> 0.19 | J4: =ROUND(H4*I4,0) -> 147003 | K4: =H4+J4 -> 920703 | L4: =INDEX($X$2:$X$31,MATCH(C4,$V$2:$V$31,0)) -> 0.04 | M4: =ROUND(H4*L4,0) -> 30948 | N4: =IF(I4=0,0,0.15) -> 0.15 | O4: =ROUND(J4*N4,0) -> 22050 | P4: =0.01104 -> 0.01104 | Q4: =ROUND(H4*P4,0) -> 8542 | R4: =K4-M4-O4-Q4 -> 859163 | S4: =CHOOSE(RANDBETWEEN(1,3),"Transferencia","Efectivo","Tarjeta crédito") -> Efectivo | T4: =IF(RANDBETWEEN(1,10)<=8,"Pagado","Pendiente") -> Pagado | V4: Servicio de acueducto y alcantarillado | W4: Servicios Públicos | X4: 0 | Y4: Tigo UNE Telecomunicaciones S.A. | Z4: 830122566-1 | AB4: Bodega | AC4: Tarjeta crédito
A5: ="GA-"&TEXT(2000+ROW()-2,"0000") -> GA-2003 | B5: =DATE(2026,1,1)+RANDBETWEEN(0,119) -> 46098 | C5: {=INDEX($V$2:$V$31,RANDBETWEEN(1,30))} -> Peajes y parqueaderos | D5: {=INDEX($Y$2:$Y$26,RANDBETWEEN(1,25))} -> EPM - Empresas Públicas de Medellín | E5: =INDEX($Z$2:$Z$26,MATCH(D5,$Y$2:$Y$26,0)) -> 890904996-1 | F5: =INDEX($W$2:$W$31,MATCH(C5,$V$2:$V$31,0)) -> Transporte | G5: {=INDEX($AB$2:$AB$6,RANDBETWEEN(1,5))} -> Gerencia | H5: =ROUND(RANDBETWEEN(150000,8500000),-2) -> 4880000 | I5: =IF(OR(F5="Servicios Públicos",F5="Financieros",F5="Legales",F5="Seguros"),0,0.19) -> 0.19 | J5: =ROUND(H5*I5,0) -> 927200 | K5: =H5+J5 -> 5807200 | L5: =INDEX($X$2:$X$31,MATCH(C5,$V$2:$V$31,0)) -> 0 | M5: =ROUND(H5*L5,0) -> 0 | N5: =IF(I5=0,0,0.15) -> 0.15 | O5: =ROUND(J5*N5,0) -> 139080 | P5: =0.01104 -> 0.01104 | Q5: =ROUND(H5*P5,0) -> 53875 | R5: =K5-M5-O5-Q5 -> 5614245 | S5: =CHOOSE(RANDBETWEEN(1,3),"Transferencia","Efectivo","Tarjeta crédito") -> Tarjeta crédito | T5: =IF(RANDBETWEEN(1,10)<=8,"Pagado","Pendiente") -> Pagado | V5: Servicio de gas natural | W5: Servicios Públicos | X5: 0 | Y5: Claro Colombia Móvil S.A. | Z5: 830114921-1 | AB5: Logística
A6: ="GA-"&TEXT(2000+ROW()-2,"0000") -> GA-2004 | B6: =DATE(2026,1,1)+RANDBETWEEN(0,119) -> 46114 | C6: {=INDEX($V$2:$V$31,RANDBETWEEN(1,30))} -> Plataforma facturación electrónica | D6: {=INDEX($Y$2:$Y$26,RANDBETWEEN(1,25))} -> TecnoSoporte Paisa S.A.S. | E6: =INDEX($Z$2:$Z$26,MATCH(D6,$Y$2:$Y$26,0)) -> 901456789-6 | F6: =INDEX($W$2:$W$31,MATCH(C6,$V$2:$V$31,0)) -> Tecnología | G6: {=INDEX($AB$2:$AB$6,RANDBETWEEN(1,5))} -> Gerencia | H6: =ROUND(RANDBETWEEN(150000,8500000),-2) -> 7766000 | I6: =IF(OR(F6="Servicios Públicos",F6="Financieros",F6="Legales",F6="Seguros"),0,0.19) -> 0.19 | J6: =ROUND(H6*I6,0) -> 1475540 | K6: =H6+J6 -> 9241540 | L6: =INDEX($X$2:$X$31,MATCH(C6,$V$2:$V$31,0)) -> 0.035 | M6: =ROUND(H6*L6,0) -> 271810 | N6: =IF(I6=0,0,0.15) -> 0.15 | O6: =ROUND(J6*N6,0) -> 221331 | P6: =0.01104 -> 0.01104 | Q6: =ROUND(H6*P6,0) -> 85737 | R6: =K6-M6-O6-Q6 -> 8662662 | S6: =CHOOSE(RANDBETWEEN(1,3),"Transferencia","Efectivo","Tarjeta crédito") -> Tarjeta crédito | T6: =IF(RANDBETWEEN(1,10)<=8,"Pagado","Pendiente") -> Pagado | V6: Servicio de internet y telefonía | W6: Servicios Públicos | X6: 0.04 | Y6: Contadores Asociados Antioquia S.A.S. | Z6: 901234567-2 | AB6: Gerencia
A7: ="GA-"&TEXT(2000+ROW()-2,"0000") -> GA-2005 | B7: =DATE(2026,1,1)+RANDBETWEEN(0,119) -> 46138 | C7: {=INDEX($V$2:$V$31,RANDBETWEEN(1,30))} -> Pólizas de seguros comerciales | D7: {=INDEX($Y$2:$Y$26,RANDBETWEEN(1,25))} -> Fumigaciones Sanitarias Envigado | E7: =INDEX($Z$2:$Z$26,MATCH(D7,$Y$2:$Y$26,0)) -> 901901234-8 | F7: =INDEX($W$2:$W$31,MATCH(C7,$V$2:$V$31,0)) -> Seguros | G7: {=INDEX($AB$2:$AB$6,RANDBETWEEN(1,5))} -> Gerencia | H7: =ROUND(RANDBETWEEN(150000,8500000),-2) -> 4996300 | I7: =IF(OR(F7="Servicios Públicos",F7="Financieros",F7="Legales",F7="Seguros"),0,0.19) -> 0 | J7: =ROUND(H7*I7,0) -> 0 | K7: =H7+J7 -> 4996300 | L7: =INDEX($X$2:$X$31,MATCH(C7,$V$2:$V$31,0)) -> 0.024 | M7: =ROUND(H7*L7,0) -> 119911 | N7: =IF(I7=0,0,0.15) -> 0 | O7: =ROUND(J7*N7,0) -> 0 | P7: =0.01104 -> 0.01104 | Q7: =ROUND(H7*P7,0) -> 55159 | R7: =K7-M7-O7-Q7 -> 4821230 | S7: =CHOOSE(RANDBETWEEN(1,3),"Transferencia","Efectivo","Tarjeta crédito") -> Tarjeta crédito | T7: =IF(RANDBETWEEN(1,10)<=8,"Pagado","Pendiente") -> Pagado | V7: Honorarios contables | W7: Honorarios | X7: 0.11 | Y7: Bufete Jurídico Aburrá Ltda. | Z7: 901345678-3
A8: ="GA-"&TEXT(2000+ROW()-2,"0000") -> GA-2006 | B8: =DATE(2026,1,1)+RANDBETWEEN(0,119) -> 46125 | C8: {=INDEX($V$2:$V$31,RANDBETWEEN(1,30))} -> Software contable - licencia mensual | D8: {=INDEX($Y$2:$Y$26,RANDBETWEEN(1,25))} -> Inmobiliaria El Poblado S.A.S. | E8: =INDEX($Z$2:$Z$26,MATCH(D8,$Y$2:$Y$26,0)) -> 900456789-1 | F8: =INDEX($W$2:$W$31,MATCH(C8,$V$2:$V$31,0)) -> Tecnología | G8: {=INDEX($AB$2:$AB$6,RANDBETWEEN(1,5))} -> Gerencia | H8: =ROUND(RANDBETWEEN(150000,8500000),-2) -> 806500 | I8: =IF(OR(F8="Servicios Públicos",F8="Financieros",F8="Legales",F8="Seguros"),0,0.19) -> 0.19 | J8: =ROUND(H8*I8,0) -> 153235 | K8: =H8+J8 -> 959735 | L8: =INDEX($X$2:$X$31,MATCH(C8,$V$2:$V$31,0)) -> 0.035 | M8: =ROUND(H8*L8,0) -> 28228 | N8: =IF(I8=0,0,0.15) -> 0.15 | O8: =ROUND(J8*N8,0) -> 22985 | P8: =0.01104 -> 0.01104 | Q8: =ROUND(H8*P8,0) -> 8904 | R8: =K8-M8-O8-Q8 -> 899618 | S8: =CHOOSE(RANDBETWEEN(1,3),"Transferencia","Efectivo","Tarjeta crédito") -> Efectivo | T8: =IF(RANDBETWEEN(1,10)<=8,"Pagado","Pendiente") -> Pagado | V8: Honorarios asesoría jurídica | W8: Honorarios | X8: 0.11 | Y8: Aseo Total Medellín S.A.S. | Z8: 900567890-4
A9: ="GA-"&TEXT(2000+ROW()-2,"0000") -> GA-2007 | B9: =DATE(2026,1,1)+RANDBETWEEN(0,119) -> 46130 | C9: {=INDEX($V$2:$V$31,RANDBETWEEN(1,30))} -> Honorarios revisoría fiscal | D9: {=INDEX($Y$2:$Y$26,RANDBETWEEN(1,25))} -> Software Contable Siigo S.A. | E9: =INDEX($Z$2:$Z$26,MATCH(D9,$Y$2:$Y$26,0)) -> 830067335-9 | F9: =INDEX($W$2:$W$31,MATCH(C9,$V$2:$V$31,0)) -> Honorarios | G9: {=INDEX($AB$2:$AB$6,RANDBETWEEN(1,5))} -> Logística | H9: =ROUND(RANDBETWEEN(150000,8500000),-2) -> 6869200 | I9: =IF(OR(F9="Servicios Públicos",F9="Financieros",F9="Legales",F9="Seguros"),0,0.19) -> 0.19 | J9: =ROUND(H9*I9,0) -> 1305148 | K9: =H9+J9 -> 8174348 | L9: =INDEX($X$2:$X$31,MATCH(C9,$V$2:$V$31,0)) -> 0.11 | M9: =ROUND(H9*L9,0) -> 755612 | N9: =IF(I9=0,0,0.15) -> 0.15 | O9: =ROUND(J9*N9,0) -> 195772 | P9: =0.01104 -> 0.01104 | Q9: =ROUND(H9*P9,0) -> 75836 | R9: =K9-M9-O9-Q9 -> 7147128 | S9: =CHOOSE(RANDBETWEEN(1,3),"Transferencia","Efectivo","Tarjeta crédito") -> Tarjeta crédito | T9: =IF(RANDBETWEEN(1,10)<=8,"Pagado","Pendiente") -> Pendiente | V9: Honorarios revisoría fiscal | W9: Honorarios | X9: 0.11 | Y9: Vigilancia Andina Seguridad Ltda. | Z9: 800678901-5
A10: ="GA-"&TEXT(2000+ROW()-2,"0000") -> GA-2008 | B10: =DATE(2026,1,1)+RANDBETWEEN(0,119) -> 46047 | C10: {=INDEX($V$2:$V$31,RANDBETWEEN(1,30))} -> Arrendamiento local comercial | D10: {=INDEX($Y$2:$Y$26,RANDBETWEEN(1,25))} -> Bufete Jurídico Aburrá Ltda. | E10: =INDEX($Z$2:$Z$26,MATCH(D10,$Y$2:$Y$26,0)) -> 901345678-3 | F10: =INDEX($W$2:$W$31,MATCH(C10,$V$2:$V$31,0)) -> Arrendamientos | G10: {=INDEX($AB$2:$AB$6,RANDBETWEEN(1,5))} -> Bodega | H10: =ROUND(RANDBETWEEN(150000,8500000),-2) -> 5728000 | I10: =IF(OR(F10="Servicios Públicos",F10="Financieros",F10="Legales",F10="Seguros"),0,0.19) -> 0.19 | J10: =ROUND(H10*I10,0) -> 1088320 | K10: =H10+J10 -> 6816320 | L10: =INDEX($X$2:$X$31,MATCH(C10,$V$2:$V$31,0)) -> 0.035 | M10: =ROUND(H10*L10,0) -> 200480 | N10: =IF(I10=0,0,0.15) -> 0.15 | O10: =ROUND(J10*N10,0) -> 163248 | P10: =0.01104 -> 0.01104 | Q10: =ROUND(H10*P10,0) -> 63237 | R10: =K10-M10-O10-Q10 -> 6389355 | S10: =CHOOSE(RANDBETWEEN(1,3),"Transferencia","Efectivo","Tarjeta crédito") -> Transferencia | T10: =IF(RANDBETWEEN(1,10)<=8,"Pagado","Pendiente") -> Pagado | V10: Servicios de aseo y cafetería | W10: Servicios | X10: 0.04 | Y10: TecnoSoporte Paisa S.A.S. | Z10: 901456789-6
A11: ="GA-"&TEXT(2000+ROW()-2,"0000") -> GA-2009 | B11: =DATE(2026,1,1)+RANDBETWEEN(0,119) -> 46092 | C11: {=INDEX($V$2:$V$31,RANDBETWEEN(1,30))} -> Honorarios asesoría jurídica | D11: {=INDEX($Y$2:$Y$26,RANDBETWEEN(1,25))} -> Bancolombia S.A. | E11: =INDEX($Z$2:$Z$26,MATCH(D11,$Y$2:$Y$26,0)) -> 890903938-8 | F11: =INDEX($W$2:$W$31,MATCH(C11,$V$2:$V$31,0)) -> Honorarios | G11: {=INDEX($AB$2:$AB$6,RANDBETWEEN(1,5))} -> Bodega | H11: =ROUND(RANDBETWEEN(150000,8500000),-2) -> 2512600 | I11: =IF(OR(F11="Servicios Públicos",F11="Financieros",F11="Legales",F11="Seguros"),0,0.19) -> 0.19 | J11: =ROUND(H11*I11,0) -> 477394 | K11: =H11+J11 -> 2989994 | L11: =INDEX($X$2:$X$31,MATCH(C11,$V$2:$V$31,0)) -> 0.11 | M11: =ROUND(H11*L11,0) -> 276386 | N11: =IF(I11=0,0,0.15) -> 0.15 | O11: =ROUND(J11*N11,0) -> 71609 | P11: =0.01104 -> 0.01104 | Q11: =ROUND(H11*P11,0) -> 27739 | R11: =K11-M11-O11-Q11 -> 2614260 | S11: =CHOOSE(RANDBETWEEN(1,3),"Transferencia","Efectivo","Tarjeta crédito") -> Tarjeta crédito | T11: =IF(RANDBETWEEN(1,10)<=8,"Pagado","Pendiente") -> Pagado | V11: Servicio de vigilancia privada | W11: Servicios | X11: 0.02 | Y11: Constructora Mantenimientos Bello | Z11: 900789012-7
A12: ="GA-"&TEXT(2000+ROW()-2,"0000") -> GA-2010 | B12: =DATE(2026,1,1)+RANDBETWEEN(0,119) -> 46071 | C12: {=INDEX($V$2:$V$31,RANDBETWEEN(1,30))} -> Combustible vehículo de reparto | D12: {=INDEX($Y$2:$Y$26,RANDBETWEEN(1,25))} -> TecnoSoporte Paisa S.A.S. | E12: =INDEX($Z$2:$Z$26,MATCH(D12,$Y$2:$Y$26,0)) -> 901456789-6 | F12: =INDEX($W$2:$W$31,MATCH(C12,$V$2:$V$31,0)) -> Transporte | G12: {=INDEX($AB$2:$AB$6,RANDBETWEEN(1,5))} -> Ventas | H12: =ROUND(RANDBETWEEN(150000,8500000),-2) -> 1297900 | I12: =IF(OR(F12="Servicios Públicos",F12="Financieros",F12="Legales",F12="Seguros"),0,0.19) -> 0.19 | J12: =ROUND(H12*I12,0) -> 246601 | K12: =H12+J12 -> 1544501 | L12: =INDEX($X$2:$X$31,MATCH(C12,$V$2:$V$31,0)) -> 0.001 | M12: =ROUND(H12*L12,0) -> 1298 | N12: =IF(I12=0,0,0.15) -> 0.15 | O12: =ROUND(J12*N12,0) -> 36990 | P12: =0.01104 -> 0.01104 | Q12: =ROUND(H12*P12,0) -> 14329 | R12: =K12-M12-O12-Q12 -> 1491884 | S12: =CHOOSE(RANDBETWEEN(1,3),"Transferencia","Efectivo","Tarjeta crédito") -> Transferencia | T12: =IF(RANDBETWEEN(1,10)<=8,"Pagado","Pendiente") -> Pendiente | V12: Mantenimiento equipos de cómputo | W12: Mantenimiento | X12: 0.04 | Y12: Papelería La Candelaria S.A.S. | Z12: 890567123-8
A13: ="GA-"&TEXT(2000+ROW()-2,"0000") -> GA-2011 | B13: =DATE(2026,1,1)+RANDBETWEEN(0,119) -> 46059 | C13: {=INDEX($V$2:$V$31,RANDBETWEEN(1,30))} -> Peajes y parqueaderos | D13: {=INDEX($Y$2:$Y$26,RANDBETWEEN(1,25))} -> Software Contable Siigo S.A. | E13: =INDEX($Z$2:$Z$26,MATCH(D13,$Y$2:$Y$26,0)) -> 830067335-9 | F13: =INDEX($W$2:$W$31,MATCH(C13,$V$2:$V$31,0)) -> Transporte | G13: {=INDEX($AB$2:$AB$6,RANDBETWEEN(1,5))} -> Gerencia | H13: =ROUND(RANDBETWEEN(150000,8500000),-2) -> 5524300 | I13: =IF(OR(F13="Servicios Públicos",F13="Financieros",F13="Legales",F13="Seguros"),0,0.19) -> 0.19 | J13: =ROUND(H13*I13,0) -> 1049617 | K13: =H13+J13 -> 6573917 | L13: =INDEX($X$2:$X$31,MATCH(C13,$V$2:$V$31,0)) -> 0 | M13: =ROUND(H13*L13,0) -> 0 | N13: =IF(I13=0,0,0.15) -> 0.15 | O13: =ROUND(J13*N13,0) -> 157443 | P13: =0.01104 -> 0.01104 | Q13: =ROUND(H13*P13,0) -> 60988 | R13: =K13-M13-O13-Q13 -> 6355486 | S13: =CHOOSE(RANDBETWEEN(1,3),"Transferencia","Efectivo","Tarjeta crédito") -> Efectivo | T13: =IF(RANDBETWEEN(1,10)<=8,"Pagado","Pendiente") -> Pendiente | V13: Mantenimiento locativo del local | W13: Mantenimiento | X13: 0.02 | Y13: Software Contable Siigo S.A. | Z13: 830067335-9
A14: ="GA-"&TEXT(2000+ROW()-2,"0000") -> GA-2012 | B14: =DATE(2026,1,1)+RANDBETWEEN(0,119) -> 46106 | C14: {=INDEX($V$2:$V$31,RANDBETWEEN(1,30))} -> Combustible vehículo de reparto | D14: {=INDEX($Y$2:$Y$26,RANDBETWEEN(1,25))} -> Tigo UNE Telecomunicaciones S.A. | E14: =INDEX($Z$2:$Z$26,MATCH(D14,$Y$2:$Y$26,0)) -> 830122566-1 | F14: =INDEX($W$2:$W$31,MATCH(C14,$V$2:$V$31,0)) -> Transporte | G14: {=INDEX($AB$2:$AB$6,RANDBETWEEN(1,5))} -> Administración | H14: =ROUND(RANDBETWEEN(150000,8500000),-2) -> 8411300 | I14: =IF(OR(F14="Servicios Públicos",F14="Financieros",F14="Legales",F14="Seguros"),0,0.19) -> 0.19 | J14: =ROUND(H14*I14,0) -> 1598147 | K14: =H14+J14 -> 10009447 | L14: =INDEX($X$2:$X$31,MATCH(C14,$V$2:$V$31,0)) -> 0.001 | M14: =ROUND(H14*L14,0) -> 8411 | N14: =IF(I14=0,0,0.15) -> 0.15 | O14: =ROUND(J14*N14,0) -> 239722 | P14: =0.01104 -> 0.01104 | Q14: =ROUND(H14*P14,0) -> 92861 | R14: =K14-M14-O14-Q14 -> 9668453 | S14: =CHOOSE(RANDBETWEEN(1,3),"Transferencia","Efectivo","Tarjeta crédito") -> Transferencia | T14: =IF(RANDBETWEEN(1,10)<=8,"Pagado","Pendiente") -> Pagado | V14: Papelería y útiles de oficina | W14: Suministros | X14: 0.025 | Y14: Facturación Electrónica Alegra S.A.S. | Z14: 900912345-0
A15: ="GA-"&TEXT(2000+ROW()-2,"0000") -> GA-2013 | B15: =DATE(2026,1,1)+RANDBETWEEN(0,119) -> 46102 | C15: {=INDEX($V$2:$V$31,RANDBETWEEN(1,30))} -> Servicio de gas natural | D15: {=INDEX($Y$2:$Y$26,RANDBETWEEN(1,25))} -> Imprenta Suramericana Ltda. | E15: =INDEX($Z$2:$Z$26,MATCH(D15,$Y$2:$Y$26,0)) -> 890345678-2 | F15: =INDEX($W$2:$W$31,MATCH(C15,$V$2:$V$31,0)) -> Servicios Públicos | G15: {=INDEX($AB$2:$AB$6,RANDBETWEEN(1,5))} -> Logística | H15: =ROUND(RANDBETWEEN(150000,8500000),-2) -> 2225000 | I15: =IF(OR(F15="Servicios Públicos",F15="Financieros",F15="Legales",F15="Seguros"),0,0.19) -> 0 | J15: =ROUND(H15*I15,0) -> 0 | K15: =H15+J15 -> 2225000 | L15: =INDEX($X$2:$X$31,MATCH(C15,$V$2:$V$31,0)) -> 0 | M15: =ROUND(H15*L15,0) -> 0 | N15: =IF(I15=0,0,0.15) -> 0 | O15: =ROUND(J15*N15,0) -> 0 | P15: =0.01104 -> 0.01104 | Q15: =ROUND(H15*P15,0) -> 24564 | R15: =K15-M15-O15-Q15 -> 2200436 | S15: =CHOOSE(RANDBETWEEN(1,3),"Transferencia","Efectivo","Tarjeta crédito") -> Transferencia | T15: =IF(RANDBETWEEN(1,10)<=8,"Pagado","Pendiente") -> Pagado | V15: Tóner y suministros de impresora | W15: Suministros | X15: 0.025 | Y15: Agencia Digital Laureles S.A.S. | Z15: 901567890-1
A16: ="GA-"&TEXT(2000+ROW()-2,"0000") -> GA-2014 | B16: =DATE(2026,1,1)+RANDBETWEEN(0,119) -> 46129 | C16: {=INDEX($V$2:$V$31,RANDBETWEEN(1,30))} -> Servicio de internet y telefonía | D16: {=INDEX($Y$2:$Y$26,RANDBETWEEN(1,25))} -> Servientrega S.A. | E16: =INDEX($Z$2:$Z$26,MATCH(D16,$Y$2:$Y$26,0)) -> 860512330-3 | F16: =INDEX($W$2:$W$31,MATCH(C16,$V$2:$V$31,0)) -> Servicios Públicos | G16: {=INDEX($AB$2:$AB$6,RANDBETWEEN(1,5))} -> Administración | H16: =ROUND(RANDBETWEEN(150000,8500000),-2) -> 6301100 | I16: =IF(OR(F16="Servicios Públicos",F16="Financieros",F16="Legales",F16="Seguros"),0,0.19) -> 0 | J16: =ROUND(H16*I16,0) -> 0 | K16: =H16+J16 -> 6301100 | L16: =INDEX($X$2:$X$31,MATCH(C16,$V$2:$V$31,0)) -> 0.04 | M16: =ROUND(H16*L16,0) -> 252044 | N16: =IF(I16=0,0,0.15) -> 0 | O16: =ROUND(J16*N16,0) -> 0 | P16: =0.01104 -> 0.01104 | Q16: =ROUND(H16*P16,0) -> 69564 | R16: =K16-M16-O16-Q16 -> 5979492 | S16: =CHOOSE(RANDBETWEEN(1,3),"Transferencia","Efectivo","Tarjeta crédito") -> Transferencia | T16: =IF(RANDBETWEEN(1,10)<=8,"Pagado","Pendiente") -> Pagado | V16: Software contable - licencia mensual | W16: Tecnología | X16: 0.035 | Y16: Imprenta Suramericana Ltda. | Z16: 890345678-2
A17: ="GA-"&TEXT(2000+ROW()-2,"0000") -> GA-2015 | B17: =DATE(2026,1,1)+RANDBETWEEN(0,119) -> 46120 | C17: {=INDEX($V$2:$V$31,RANDBETWEEN(1,30))} -> Tóner y suministros de impresora | D17: {=INDEX($Y$2:$Y$26,RANDBETWEEN(1,25))} -> Tigo UNE Telecomunicaciones S.A. | E17: =INDEX($Z$2:$Z$26,MATCH(D17,$Y$2:$Y$26,0)) -> 830122566-1 | F17: =INDEX($W$2:$W$31,MATCH(C17,$V$2:$V$31,0)) -> Suministros | G17: {=INDEX($AB$2:$AB$6,RANDBETWEEN(1,5))} -> Ventas | H17: =ROUND(RANDBETWEEN(150000,8500000),-2) -> 7543900 | I17: =IF(OR(F17="Servicios Públicos",F17="Financieros",F17="Legales",F17="Seguros"),0,0.19) -> 0.19 | J17: =ROUND(H17*I17,0) -> 1433341 | K17: =H17+J17 -> 8977241 | L17: =INDEX($X$2:$X$31,MATCH(C17,$V$2:$V$31,0)) -> 0.025 | M17: =ROUND(H17*L17,0) -> 188598 | N17: =IF(I17=0,0,0.15) -> 0.15 | O17: =ROUND(J17*N17,0) -> 215001 | P17: =0.01104 -> 0.01104 | Q17: =ROUND(H17*P17,0) -> 83285 | R17: =K17-M17-O17-Q17 -> 8490357 | S17: =CHOOSE(RANDBETWEEN(1,3),"Transferencia","Efectivo","Tarjeta crédito") -> Transferencia | T17: =IF(RANDBETWEEN(1,10)<=8,"Pagado","Pendiente") -> Pagado | V17: Plataforma facturación electrónica | W17: Tecnología | X17: 0.035 | Y17: Centro de Capacitación SST Antioquia | Z17: 901678901-3
A18: ="GA-"&TEXT(2000+ROW()-2,"0000") -> GA-2016 | B18: =DATE(2026,1,1)+RANDBETWEEN(0,119) -> 46124 | C18: {=INDEX($V$2:$V$31,RANDBETWEEN(1,30))} -> Pólizas de seguros comerciales | D18: {=INDEX($Y$2:$Y$26,RANDBETWEEN(1,25))} -> EPM - Empresas Públicas de Medellín | E18: =INDEX($Z$2:$Z$26,MATCH(D18,$Y$2:$Y$26,0)) -> 890904996-1 | F18: =INDEX($W$2:$W$31,MATCH(C18,$V$2:$V$31,0)) -> Seguros | G18: {=INDEX($AB$2:$AB$6,RANDBETWEEN(1,5))} -> Ventas | H18: =ROUND(RANDBETWEEN(150000,8500000),-2) -> 3512200 | I18: =IF(OR(F18="Servicios Públicos",F18="Financieros",F18="Legales",F18="Seguros"),0,0.19) -> 0 | J18: =ROUND(H18*I18,0) -> 0 | K18: =H18+J18 -> 3512200 | L18: =INDEX($X$2:$X$31,MATCH(C18,$V$2:$V$31,0)) -> 0.024 | M18: =ROUND(H18*L18,0) -> 84293 | N18: =IF(I18=0,0,0.15) -> 0 | O18: =ROUND(J18*N18,0) -> 0 | P18: =0.01104 -> 0.01104 | Q18: =ROUND(H18*P18,0) -> 38775 | R18: =K18-M18-O18-Q18 -> 3389132 | S18: =CHOOSE(RANDBETWEEN(1,3),"Transferencia","Efectivo","Tarjeta crédito") -> Efectivo | T18: =IF(RANDBETWEEN(1,10)<=8,"Pagado","Pendiente") -> Pagado | V18: Publicidad redes sociales | W18: Publicidad | X18: 0.04 | Y18: EDS Texaco La 80 | Z18: 800123456-4
... A26: ="GA-"&TEXT(2000+ROW()-2,"0000") -> GA-2024 | B26: =DATE(2026,1,1)+RANDBETWEEN(0,119) -> 46081 | C26: {=INDEX($V$2:$V$31,RANDBETWEEN(1,30))} -> Honorarios contables | D26: {=INDEX($Y$2:$Y$26,RANDBETWEEN(1,25))} -> Inmobiliaria El Poblado S.A.S. | E26: =INDEX($Z$2:$Z$26,MATCH(D26,$Y$2:$Y$26,0)) -> 900456789-1 | F26: =INDEX($W$2:$W$31,MATCH(C26,$V$2:$V$31,0)) -> Honorarios | G26: {=INDEX($AB$2:$AB$6,RANDBETWEEN(1,5))} -> Ventas | H26: =ROUND(RANDBETWEEN(150000,8500000),-2) -> 3909100 | I26: =IF(OR(F26="Servicios Públicos",F26="Financieros",F26="Legales",F26="Seguros"),0,0.19) -> 0.19 | J26: =ROUND(H26*I26,0) -> 742729 | K26: =H26+J26 -> 4651829 | L26: =INDEX($X$2:$X$31,MATCH(C26,$V$2:$V$31,0)) -> 0.11 | M26: =ROUND(H26*L26,0) -> 430001 | N26: =IF(I26=0,0,0.15) -> 0.15 | O26: =ROUND(J26*N26,0) -> 111409 | P26: =0.01104 -> 0.01104 | Q26: =ROUND(H26*P26,0) -> 43156 | R26: =K26-M26-O26-Q26 -> 4067263 | S26: =CHOOSE(RANDBETWEEN(1,3),"Transferencia","Efectivo","Tarjeta crédito") -> Efectivo | T26: =IF(RANDBETWEEN(1,10)<=8,"Pagado","Pendiente") -> Pagado | V26: Servicio de courier y mensajería | W26: Servicios | X26: 0.04 | Y26: Fumigaciones Sanitarias Envigado | Z26: 901901234-8
A27: ="GA-"&TEXT(2000+ROW()-2,"0000") -> GA-2025 | B27: =DATE(2026,1,1)+RANDBETWEEN(0,119) -> 46130 | C27: {=INDEX($V$2:$V$31,RANDBETWEEN(1,30))} -> Servicio de fumigación local | D27: {=INDEX($Y$2:$Y$26,RANDBETWEEN(1,25))} -> Vigilancia Andina Seguridad Ltda. | E27: =INDEX($Z$2:$Z$26,MATCH(D27,$Y$2:$Y$26,0)) -> 800678901-5 | F27: =INDEX($W$2:$W$31,MATCH(C27,$V$2:$V$31,0)) -> Mantenimiento | G27: {=INDEX($AB$2:$AB$6,RANDBETWEEN(1,5))} -> Bodega | H27: =ROUND(RANDBETWEEN(150000,8500000),-2) -> 5597700 | I27: =IF(OR(F27="Servicios Públicos",F27="Financieros",F27="Legales",F27="Seguros"),0,0.19) -> 0.19 | J27: =ROUND(H27*I27,0) -> 1063563 | K27: =H27+J27 -> 6661263 | L27: =INDEX($X$2:$X$31,MATCH(C27,$V$2:$V$31,0)) -> 0.04 | M27: =ROUND(H27*L27,0) -> 223908 | N27: =IF(I27=0,0,0.15) -> 0.15 | O27: =ROUND(J27*N27,0) -> 159534 | P27: =0.01104 -> 0.01104 | Q27: =ROUND(H27*P27,0) -> 61799 | R27: =K27-M27-O27-Q27 -> 6216022 | S27: =CHOOSE(RANDBETWEEN(1,3),"Transferencia","Efectivo","Tarjeta crédito") -> Tarjeta crédito | T27: =IF(RANDBETWEEN(1,10)<=8,"Pagado","Pendiente") -> Pagado | V27: Pólizas de seguros comerciales | W27: Seguros | X27: 0.024
A28: ="GA-"&TEXT(2000+ROW()-2,"0000") -> GA-2026 | B28: =DATE(2026,1,1)+RANDBETWEEN(0,119) -> 46132 | C28: {=INDEX($V$2:$V$31,RANDBETWEEN(1,30))} -> Servicio de internet y telefonía | D28: {=INDEX($Y$2:$Y$26,RANDBETWEEN(1,25))} -> Centro de Capacitación SST Antioquia | E28: =INDEX($Z$2:$Z$26,MATCH(D28,$Y$2:$Y$26,0)) -> 901678901-3 | F28: =INDEX($W$2:$W$31,MATCH(C28,$V$2:$V$31,0)) -> Servicios Públicos | G28: {=INDEX($AB$2:$AB$6,RANDBETWEEN(1,5))} -> Ventas | H28: =ROUND(RANDBETWEEN(150000,8500000),-2) -> 7968800 | I28: =IF(OR(F28="Servicios Públicos",F28="Financieros",F28="Legales",F28="Seguros"),0,0.19) -> 0 | J28: =ROUND(H28*I28,0) -> 0 | K28: =H28+J28 -> 7968800 | L28: =INDEX($X$2:$X$31,MATCH(C28,$V$2:$V$31,0)) -> 0.04 | M28: =ROUND(H28*L28,0) -> 318752 | N28: =IF(I28=0,0,0.15) -> 0 | O28: =ROUND(J28*N28,0) -> 0 | P28: =0.01104 -> 0.01104 | Q28: =ROUND(H28*P28,0) -> 87976 | R28: =K28-M28-O28-Q28 -> 7562072 | S28: =CHOOSE(RANDBETWEEN(1,3),"Transferencia","Efectivo","Tarjeta crédito") -> Efectivo | T28: =IF(RANDBETWEEN(1,10)<=8,"Pagado","Pendiente") -> Pagado | V28: Suscripción cámara de comercio | W28: Legales | X28: 0
A29: ="GA-"&TEXT(2000+ROW()-2,"0000") -> GA-2027 | B29: =DATE(2026,1,1)+RANDBETWEEN(0,119) -> 46038 | C29: {=INDEX($V$2:$V$31,RANDBETWEEN(1,30))} -> Tóner y suministros de impresora | D29: {=INDEX($Y$2:$Y$26,RANDBETWEEN(1,25))} -> Papelería La Candelaria S.A.S. | E29: =INDEX($Z$2:$Z$26,MATCH(D29,$Y$2:$Y$26,0)) -> 890567123-8 | F29: =INDEX($W$2:$W$31,MATCH(C29,$V$2:$V$31,0)) -> Suministros | G29: {=INDEX($AB$2:$AB$6,RANDBETWEEN(1,5))} -> Gerencia | H29: =ROUND(RANDBETWEEN(150000,8500000),-2) -> 1117200 | I29: =IF(OR(F29="Servicios Públicos",F29="Financieros",F29="Legales",F29="Seguros"),0,0.19) -> 0.19 | J29: =ROUND(H29*I29,0) -> 212268 | K29: =H29+J29 -> 1329468 | L29: =INDEX($X$2:$X$31,MATCH(C29,$V$2:$V$31,0)) -> 0.025 | M29: =ROUND(H29*L29,0) -> 27930 | N29: =IF(I29=0,0,0.15) -> 0.15 | O29: =ROUND(J29*N29,0) -> 31840 | P29: =0.01104 -> 0.01104 | Q29: =ROUND(H29*P29,0) -> 12334 | R29: =K29-M29-O29-Q29 -> 1257364 | S29: =CHOOSE(RANDBETWEEN(1,3),"Transferencia","Efectivo","Tarjeta crédito") -> Tarjeta crédito | T29: =IF(RANDBETWEEN(1,10)<=8,"Pagado","Pendiente") -> Pagado | V29: Servicios bancarios y comisiones | W29: Financieros | X29: 0
A30: ="GA-"&TEXT(2000+ROW()-2,"0000") -> GA-2028 | B30: =DATE(2026,1,1)+RANDBETWEEN(0,119) -> 46058 | C30: {=INDEX($V$2:$V$31,RANDBETWEEN(1,30))} -> Elementos de protección personal | D30: {=INDEX($Y$2:$Y$26,RANDBETWEEN(1,25))} -> Centro de Capacitación SST Antioquia | E30: =INDEX($Z$2:$Z$26,MATCH(D30,$Y$2:$Y$26,0)) -> 901678901-3 | F30: =INDEX($W$2:$W$31,MATCH(C30,$V$2:$V$31,0)) -> Personal | G30: {=INDEX($AB$2:$AB$6,RANDBETWEEN(1,5))} -> Logística | H30: =ROUND(RANDBETWEEN(150000,8500000),-2) -> 3425400 | I30: =IF(OR(F30="Servicios Públicos",F30="Financieros",F30="Legales",F30="Seguros"),0,0.19) -> 0.19 | J30: =ROUND(H30*I30,0) -> 650826 | K30: =H30+J30 -> 4076226 | L30: =INDEX($X$2:$X$31,MATCH(C30,$V$2:$V$31,0)) -> 0.025 | M30: =ROUND(H30*L30,0) -> 85635 | N30: =IF(I30=0,0,0.15) -> 0.15 | O30: =ROUND(J30*N30,0) -> 97624 | P30: =0.01104 -> 0.01104 | Q30: =ROUND(H30*P30,0) -> 37816 | R30: =K30-M30-O30-Q30 -> 3855151 | S30: =CHOOSE(RANDBETWEEN(1,3),"Transferencia","Efectivo","Tarjeta crédito") -> Transferencia | T30: =IF(RANDBETWEEN(1,10)<=8,"Pagado","Pendiente") -> Pagado | V30: Café, agua y refrigerios oficina | W30: Suministros | X30: 0.025
A31: ="GA-"&TEXT(2000+ROW()-2,"0000") -> GA-2029 | B31: =DATE(2026,1,1)+RANDBETWEEN(0,119) -> 46107 | C31: {=INDEX($V$2:$V$31,RANDBETWEEN(1,30))} -> Mantenimiento locativo del local | D31: {=INDEX($Y$2:$Y$26,RANDBETWEEN(1,25))} -> Tigo UNE Telecomunicaciones S.A. | E31: =INDEX($Z$2:$Z$26,MATCH(D31,$Y$2:$Y$26,0)) -> 830122566-1 | F31: =INDEX($W$2:$W$31,MATCH(C31,$V$2:$V$31,0)) -> Mantenimiento | G31: {=INDEX($AB$2:$AB$6,RANDBETWEEN(1,5))} -> Ventas | H31: =ROUND(RANDBETWEEN(150000,8500000),-2) -> 839300 | I31: =IF(OR(F31="Servicios Públicos",F31="Financieros",F31="Legales",F31="Seguros"),0,0.19) -> 0.19 | J31: =ROUND(H31*I31,0) -> 159467 | K31: =H31+J31 -> 998767 | L31: =INDEX($X$2:$X$31,MATCH(C31,$V$2:$V$31,0)) -> 0.02 | M31: =ROUND(H31*L31,0) -> 16786 | N31: =IF(I31=0,0,0.15) -> 0.15 | O31: =ROUND(J31*N31,0) -> 23920 | P31: =0.01104 -> 0.01104 | Q31: =ROUND(H31*P31,0) -> 9266 | R31: =K31-M31-O31-Q31 -> 948795 | S31: =CHOOSE(RANDBETWEEN(1,3),"Transferencia","Efectivo","Tarjeta crédito") -> Transferencia | T31: =IF(RANDBETWEEN(1,10)<=8,"Pagado","Pendiente") -> Pagado | V31: Servicio de fumigación local | W31: Mantenimiento | X31: 0.04
A32: ="GA-"&TEXT(2000+ROW()-2,"0000") -> GA-2030 | B32: =DATE(2026,1,1)+RANDBETWEEN(0,119) -> 46025 | C32: {=INDEX($V$2:$V$31,RANDBETWEEN(1,30))} -> Café, agua y refrigerios oficina | D32: {=INDEX($Y$2:$Y$26,RANDBETWEEN(1,25))} -> Tigo UNE Telecomunicaciones S.A. | E32: =INDEX($Z$2:$Z$26,MATCH(D32,$Y$2:$Y$26,0)) -> 830122566-1 | F32: =INDEX($W$2:$W$31,MATCH(C32,$V$2:$V$31,0)) -> Suministros | G32: {=INDEX($AB$2:$AB$6,RANDBETWEEN(1,5))} -> Administración | H32: =ROUND(RANDBETWEEN(150000,8500000),-2) -> 7582000 | I32: =IF(OR(F32="Servicios Públicos",F32="Financieros",F32="Legales",F32="Seguros"),0,0.19) -> 0.19 | J32: =ROUND(H32*I32,0) -> 1440580 | K32: =H32+J32 -> 9022580 | L32: =INDEX($X$2:$X$31,MATCH(C32,$V$2:$V$31,0)) -> 0.025 | M32: =ROUND(H32*L32,0) -> 189550 | N32: =IF(I32=0,0,0.15) -> 0.15 | O32: =ROUND(J32*N32,0) -> 216087 | P32: =0.01104 -> 0.01104 | Q32: =ROUND(H32*P32,0) -> 83705 | R32: =K32-M32-O32-Q32 -> 8533238 | S32: =CHOOSE(RANDBETWEEN(1,3),"Transferencia","Efectivo","Tarjeta crédito") -> Efectivo | T32: =IF(RANDBETWEEN(1,10)<=8,"Pagado","Pendiente") -> Pagado
A33: ="GA-"&TEXT(2000+ROW()-2,"0000") -> GA-2031 | B33: =DATE(2026,1,1)+RANDBETWEEN(0,119) -> 46089 | C33: {=INDEX($V$2:$V$31,RANDBETWEEN(1,30))} -> Honorarios revisoría fiscal | D33: {=INDEX($Y$2:$Y$26,RANDBETWEEN(1,25))} -> Software Contable Siigo S.A. | E33: =INDEX($Z$2:$Z$26,MATCH(D33,$Y$2:$Y$26,0)) -> 830067335-9 | F33: =INDEX($W$2:$W$31,MATCH(C33,$V$2:$V$31,0)) -> Honorarios | G33: {=INDEX($AB$2:$AB$6,RANDBETWEEN(1,5))} -> Ventas | H33: =ROUND(RANDBETWEEN(150000,8500000),-2) -> 3980700 | I33: =IF(OR(F33="Servicios Públicos",F33="Financieros",F33="Legales",F33="Seguros"),0,0.19) -> 0.19 | J33: =ROUND(H33*I33,0) -> 756333 | K33: =H33+J33 -> 4737033 | L33: =INDEX($X$2:$X$31,MATCH(C33,$V$2:$V$31,0)) -> 0.11 | M33: =ROUND(H33*L33,0) -> 437877 | N33: =IF(I33=0,0,0.15) -> 0.15 | O33: =ROUND(J33*N33,0) -> 113450 | P33: =0.01104 -> 0.01104 | Q33: =ROUND(H33*P33,0) -> 43947 | R33: =K33-M33-O33-Q33 -> 4141759 | S33: =CHOOSE(RANDBETWEEN(1,3),"Transferencia","Efectivo","Tarjeta crédito") -> Efectivo | T33: =IF(RANDBETWEEN(1,10)<=8,"Pagado","Pendiente") -> Pagado
